<?xml version="1.0" ?>
<!-- =================================================================================== -->
<!-- |    This document was autogenerated by xacro from robot.xacro                    | -->
<!-- |    EDITING THIS FILE BY HAND IS NOT RECOMMENDED                                 | -->
<!-- =================================================================================== -->
<robot name="navvis">
  <link name="base">
    <visual>
      <!-- Shift the box up half its height. !-->
      <origin rpy="0.0 0.0 0.0" xyz="0.0 0.0 0.96"/>
      <geometry>
        <box size="0.45 0.78 1.92"/>
      </geometry>
    </visual>
    <collision>
      <!-- Shift the box up half its height. !-->
      <origin rpy="0.0 0.0 0.0" xyz="0.0 0.0 0.96"/>
      <geometry>
        <box size="0.45 0.78 1.92"/>
      </geometry>
    </collision>
  </link>
  <joint name="wheel_left_joint" type="continuous">
    <parent link="base"/>
    <child link="wheel_left"/>
    <origin rpy="-1.5707963267948966 0 0" xyz="-0.1 0.4 0"/>
  </joint>
  <link name="wheel_left">
    <visual>
      <origin rpy="0.0 0.0 0.0" xyz="0.0 0.0 0.0"/>
      <geometry>
        <cylinder length="0.05" radius="0.2"/>
      </geometry>
    </visual>
    <collision>
      <origin rpy="0.0 0.0 0.0" xyz="0.0 0.0 0.0"/>
      <geometry>
        <cylinder length="0.05" radius="0.2"/>
      </geometry>
    </collision>
  </link>
  <joint name="base_laser_vert_bottom_joint" type="fixed">
    <parent link="base"/>
    <child link="laser_vert_bottom"/>
    <origin rpy="3.1355 -1.3045 0.0025" xyz="0.3158 -0.0021 0.5100"/>
  </joint>
  <link name="laser_vert_bottom">
    <visual>
      <origin rpy="0.0 0.0 0.0" xyz="0.0 0.0 0.0"/>
      <geometry>
        <box size="0.62 0.62 0.87"/>
      </geometry>
    </visual>
    <collision>
      <origin rpy="0.0 0.0 0.0" xyz="0.0 0.0 0.0"/>
      <geometry>
        <box size="0.62 0.62 0.87"/>
      </geometry>
    </collision>
  </link>
  <joint name="laser_vert_top_right_joint" type="fixed">
    <parent link="base"/>
    <child link="laser_vert_top_right"/>
    <origin rpy="-1.8451 0.6313 -1.9377" xyz="0.2978 -0.145 1.8451"/>
  </joint>
  <link name="laser_vert_top_right">
    <visual>
      <origin rpy="0.0 0.0 0.0" xyz="0.0 0.0 0.0"/>
      <geometry>
        <box size="0.62 0.62 0.87"/>
      </geometry>
    </visual>
    <collision>
      <origin rpy="0.0 0.0 0.0" xyz="0.0 0.0 0.0"/>
      <geometry>
        <box size="0.62 0.62 0.87"/>
      </geometry>
    </collision>
  </link>
  <joint name="laser_vert_top_left_joint" type="fixed">
    <parent link="base"/>
    <child link="laser_vert_top_left"/>
    <origin rpy="1.1780 0.6198 1.9560" xyz="0.2997 0.1531 1.8443"/>
  </joint>
  <link name="laser_vert_top_left">
    <visual>
      <origin rpy="0.0 0.0 0.0" xyz="0.0 0.0 0.0"/>
      <geometry>
        <box size="0.62 0.62 0.87"/>
      </geometry>
    </visual>
    <collision>
      <origin rpy="0.0 0.0 0.0" xyz="0.0 0.0 0.0"/>
      <geometry>
        <box size="0.62 0.62 0.87"/>
      </geometry>
    </collision>
  </link>
  <joint name="laser_horiz_joint" type="fixed">
    <parent link="base"/>
    <child link="laser_horiz"/>
    <origin rpy="-0.00120 0.1146 -0.0015" xyz="0.2325 0.0001 1.9201"/>
  </joint>
  <link name="laser_horiz">
    <visual>
      <origin rpy="0.0 0.0 0.0" xyz="0.0 0.0 0.0"/>
      <geometry>
        <cylinder length="0.72" radius="0.52"/>
      </geometry>
    </visual>
    <collision>
      <origin rpy="0.0 0.0 0.0" xyz="0.0 0.0 0.0"/>
      <geometry>
        <cylinder length="0.72" radius="0.52"/>
      </geometry>
    </collision>
  </link>
</robot>
